Traceback (most recent call last):
  File "/Users/amrmkayid/anaconda3/envs/kayddrl/lib/python3.6/site-packages/ray/tune/trial_runner.py", line 436, in _process_trial
    result = self.trial_executor.fetch_result(trial)
  File "/Users/amrmkayid/anaconda3/envs/kayddrl/lib/python3.6/site-packages/ray/tune/ray_trial_executor.py", line 323, in fetch_result
    result = ray.get(trial_future[0])
  File "/Users/amrmkayid/anaconda3/envs/kayddrl/lib/python3.6/site-packages/ray/worker.py", line 2195, in get
    raise value
ray.exceptions.RayTaskError: [36mray_PPO:train()[39m (pid=67999, host=KayidmacOS)
  File "/Users/amrmkayid/anaconda3/envs/kayddrl/lib/python3.6/site-packages/ray/rllib/agents/trainer_template.py", line 87, in __init__
    Trainer.__init__(self, config, env, logger_creator)
  File "/Users/amrmkayid/anaconda3/envs/kayddrl/lib/python3.6/site-packages/ray/rllib/agents/trainer.py", line 323, in __init__
    Trainable.__init__(self, config, logger_creator)
  File "/Users/amrmkayid/anaconda3/envs/kayddrl/lib/python3.6/site-packages/ray/tune/trainable.py", line 87, in __init__
    self._setup(copy.deepcopy(self.config))
  File "/Users/amrmkayid/anaconda3/envs/kayddrl/lib/python3.6/site-packages/ray/rllib/agents/trainer.py", line 424, in _setup
    self._allow_unknown_subkeys)
  File "/Users/amrmkayid/anaconda3/envs/kayddrl/lib/python3.6/site-packages/ray/tune/util.py", line 91, in deep_update
    raise Exception("Unknown config parameter `{}` ".format(k))
Exception: Unknown config parameter `on_episode_start` 

