Traceback (most recent call last):
  File "/Users/amrmkayid/anaconda3/envs/kayddrl/lib/python3.6/site-packages/ray/tune/trial_runner.py", line 436, in _process_trial
    result = self.trial_executor.fetch_result(trial)
  File "/Users/amrmkayid/anaconda3/envs/kayddrl/lib/python3.6/site-packages/ray/tune/ray_trial_executor.py", line 323, in fetch_result
    result = ray.get(trial_future[0])
  File "/Users/amrmkayid/anaconda3/envs/kayddrl/lib/python3.6/site-packages/ray/worker.py", line 2195, in get
    raise value
ray.exceptions.RayTaskError: [36mray_APEX_DDPG:train()[39m (pid=59429, host=KayidmacOS)
  File "/Users/amrmkayid/anaconda3/envs/kayddrl/lib/python3.6/site-packages/ray/rllib/agents/trainer.py", line 364, in train
    raise e
  File "/Users/amrmkayid/anaconda3/envs/kayddrl/lib/python3.6/site-packages/ray/rllib/agents/trainer.py", line 353, in train
    result = Trainable.train(self)
  File "/Users/amrmkayid/anaconda3/envs/kayddrl/lib/python3.6/site-packages/ray/tune/trainable.py", line 150, in train
    result = self._train()
  File "/Users/amrmkayid/anaconda3/envs/kayddrl/lib/python3.6/site-packages/ray/rllib/agents/trainer_template.py", line 126, in _train
    fetches = self.optimizer.step()
  File "/Users/amrmkayid/anaconda3/envs/kayddrl/lib/python3.6/site-packages/ray/rllib/optimizers/async_replay_optimizer.py", line 121, in step
    sample_timesteps, train_timesteps = self._step()
  File "/Users/amrmkayid/anaconda3/envs/kayddrl/lib/python3.6/site-packages/ray/rllib/optimizers/async_replay_optimizer.py", line 192, in _step
    counts = ray_get_and_free([c[1][1] for c in completed])
  File "/Users/amrmkayid/anaconda3/envs/kayddrl/lib/python3.6/site-packages/ray/rllib/utils/memory.py", line 33, in ray_get_and_free
    result = ray.get(object_ids)
ray.exceptions.RayTaskError: [36mray_RolloutWorker:sample_with_count()[39m (pid=59710, host=KayidmacOS)
  File "/Users/amrmkayid/anaconda3/envs/kayddrl/lib/python3.6/site-packages/psutil/_common.py", line 342, in wrapper
    ret = self._cache[fun]
AttributeError: 'Process' object has no attribute '_cache'

During handling of the above exception, another exception occurred:

[36mray_RolloutWorker:sample_with_count()[39m (pid=59710, host=KayidmacOS)
  File "/Users/amrmkayid/anaconda3/envs/kayddrl/lib/python3.6/site-packages/psutil/_common.py", line 342, in wrapper
    ret = self._cache[fun]
AttributeError: _cache

During handling of the above exception, another exception occurred:

[36mray_RolloutWorker:sample_with_count()[39m (pid=59710, host=KayidmacOS)
  File "/Users/amrmkayid/anaconda3/envs/kayddrl/lib/python3.6/site-packages/psutil/_psosx.py", line 339, in wrapper
    return fun(self, *args, **kwargs)
  File "/Users/amrmkayid/anaconda3/envs/kayddrl/lib/python3.6/site-packages/psutil/_common.py", line 345, in wrapper
    return fun(self)
  File "/Users/amrmkayid/anaconda3/envs/kayddrl/lib/python3.6/site-packages/psutil/_psosx.py", line 400, in _get_pidtaskinfo
    ret = cext.proc_pidtaskinfo_oneshot(self.pid)
PermissionError: [Errno 1] Operation not permitted

During handling of the above exception, another exception occurred:

[36mray_RolloutWorker:sample_with_count()[39m (pid=59710, host=KayidmacOS)
  File "/Users/amrmkayid/anaconda3/envs/kayddrl/lib/python3.6/site-packages/ray/memory_monitor.py", line 77, in raise_if_low_memory
    self.error_threshold))
  File "/Users/amrmkayid/anaconda3/envs/kayddrl/lib/python3.6/site-packages/ray/memory_monitor.py", line 27, in get_message
    proc_stats.append((proc.memory_info().rss, pid, proc.cmdline()))
  File "/Users/amrmkayid/anaconda3/envs/kayddrl/lib/python3.6/site-packages/psutil/_common.py", line 345, in wrapper
    return fun(self)
  File "/Users/amrmkayid/anaconda3/envs/kayddrl/lib/python3.6/site-packages/psutil/__init__.py", line 1170, in memory_info
    return self._proc.memory_info()
  File "/Users/amrmkayid/anaconda3/envs/kayddrl/lib/python3.6/site-packages/psutil/_psosx.py", line 339, in wrapper
    return fun(self, *args, **kwargs)
  File "/Users/amrmkayid/anaconda3/envs/kayddrl/lib/python3.6/site-packages/psutil/_psosx.py", line 469, in memory_info
    rawtuple = self._get_pidtaskinfo()
  File "/Users/amrmkayid/anaconda3/envs/kayddrl/lib/python3.6/site-packages/psutil/_psosx.py", line 344, in wrapper
    raise AccessDenied(self.pid, self._name)
psutil.AccessDenied: psutil.AccessDenied (pid=0)


