Traceback (most recent call last):
  File "/Users/amrmkayid/anaconda3/envs/kayddrl/lib/python3.6/site-packages/ray/tune/trial_runner.py", line 436, in _process_trial
    result = self.trial_executor.fetch_result(trial)
  File "/Users/amrmkayid/anaconda3/envs/kayddrl/lib/python3.6/site-packages/ray/tune/ray_trial_executor.py", line 323, in fetch_result
    result = ray.get(trial_future[0])
  File "/Users/amrmkayid/anaconda3/envs/kayddrl/lib/python3.6/site-packages/ray/worker.py", line 2195, in get
    raise value
ray.exceptions.RayTaskError: [36mray_PPO:train()[39m (pid=47490, host=KayidmacOS)
  File "/Users/amrmkayid/anaconda3/envs/kayddrl/lib/python3.6/site-packages/ray/rllib/agents/trainer_template.py", line 87, in __init__
    Trainer.__init__(self, config, env, logger_creator)
  File "/Users/amrmkayid/anaconda3/envs/kayddrl/lib/python3.6/site-packages/ray/rllib/agents/trainer.py", line 323, in __init__
    Trainable.__init__(self, config, logger_creator)
  File "/Users/amrmkayid/anaconda3/envs/kayddrl/lib/python3.6/site-packages/ray/tune/trainable.py", line 87, in __init__
    self._setup(copy.deepcopy(self.config))
  File "/Users/amrmkayid/anaconda3/envs/kayddrl/lib/python3.6/site-packages/ray/rllib/agents/trainer.py", line 438, in _setup
    self._init(self.config, self.env_creator)
  File "/Users/amrmkayid/anaconda3/envs/kayddrl/lib/python3.6/site-packages/ray/rllib/agents/trainer_template.py", line 106, in _init
    self.config["num_workers"])
  File "/Users/amrmkayid/anaconda3/envs/kayddrl/lib/python3.6/site-packages/ray/rllib/agents/trainer.py", line 483, in _make_workers
    logdir=self.logdir)
  File "/Users/amrmkayid/anaconda3/envs/kayddrl/lib/python3.6/site-packages/ray/rllib/evaluation/worker_set.py", line 64, in __init__
    RolloutWorker, env_creator, policy, 0, self._local_config)
  File "/Users/amrmkayid/anaconda3/envs/kayddrl/lib/python3.6/site-packages/ray/rllib/evaluation/worker_set.py", line 214, in _make_worker
    _fake_sampler=config.get("_fake_sampler", False))
  File "/Users/amrmkayid/anaconda3/envs/kayddrl/lib/python3.6/site-packages/ray/rllib/evaluation/rollout_worker.py", line 311, in __init__
    self._build_policy_map(policy_dict, policy_config)
  File "/Users/amrmkayid/anaconda3/envs/kayddrl/lib/python3.6/site-packages/ray/rllib/evaluation/rollout_worker.py", line 715, in _build_policy_map
    policy_map[name] = cls(obs_space, act_space, merged_conf)
  File "/Users/amrmkayid/anaconda3/envs/kayddrl/lib/python3.6/site-packages/ray/rllib/policy/tf_policy_template.py", line 128, in __init__
    obs_include_prev_action_reward=obs_include_prev_action_reward)
  File "/Users/amrmkayid/anaconda3/envs/kayddrl/lib/python3.6/site-packages/ray/rllib/policy/dynamic_tf_policy.py", line 97, in __init__
    action_space)
  File "/Users/amrmkayid/anaconda3/envs/kayddrl/lib/python3.6/site-packages/ray/rllib/models/catalog.py", line 197, in get_action_placeholder
    " not supported".format(action_space))
NotImplementedError: action space Dict(action_0:Box(4,), action_1:Box(4,), action_10:Box(4,), action_11:Box(4,), action_12:Box(4,), action_13:Box(4,), action_14:Box(4,), action_15:Box(4,), action_16:Box(4,), action_17:Box(4,), action_18:Box(4,), action_19:Box(4,), action_2:Box(4,), action_3:Box(4,), action_4:Box(4,), action_5:Box(4,), action_6:Box(4,), action_7:Box(4,), action_8:Box(4,), action_9:Box(4,)) not supported

